Workbook

Sheet 20260227
A1: 파트 | B1: 성명 | C1: 프로젝트명 | D1: 프로젝트코드 | E1: 진행업무 | F1: 예정업무 | G1: 비고 및 이슈
A2: =VLOOKUP(B2,기준값설정!$D$2:$E$22,2,FALSE) -> DX | B2: 정우철 | C2: 팀공통 | D2: =VLOOKUP(C2,기준값설정!$A$2:$B$22,2,FALSE) -> 공통2500 | E2: [과제 수주 및 관리] *정량적, 정성적 목표 세부사항 정리 ㄴ 과제 통합 관리 템플릿 작성 및 세부사항 정리 (초안작성완료) | F2: [과제 수주 및 관리] *정량적, 정성적 목표 세부사항 정리 ㄴ 과제 통합 관리 템플릿 작성 및 세부사항 정리 (계속) | G2: 프로젝트별 수행 계획 수립 (DX 파트) ㄴ 사업계획 기준 계획 수립 (1차 3월 2주까지)
A3: =VLOOKUP(B3,기준값설정!$D$2:$E$22,2,FALSE) -> DX | B3: 정우철 | C3: 팀공통 | D3: =VLOOKUP(C3,기준값설정!$A$2:$B$22,2,FALSE) -> 공통2500 | E3: [조직운영관리] *2026년도 팀 목표 및 KPI 수립 방향 협의 ㄴ 2026년도 팀 KPI 설정 방식 및 기준 작성 (진행중) : 초안 및 대표님 공유 ㄴ 2026년도 팀 KPI 목표 수립(진행중) : 프로젝트별 수행 계획 작성중 *2026년도 인원계획 수립 : DX, AX 파트별 충원 계획 ㄴ 대표님 제출 및 의견에 따른 TO 조정 (완료) : 총원 15~17명 *2025년도 인사평가 (완료) : 경영관리본부 제출 | F3: [조직운영관리] *2026년도 팀 목표 및 KPI 수립 방향 협의 ㄴ 2026년도 팀 KPI 설정 방식 및 기준 작성 : 대표님 협의 후 결정 (예정) ㄴ 2026년도 팀 KPI 목표 수립(진행중) : 프로젝트별 수행 계획 (예정 ~ 3월 2주) *2026년도 인원계획 수립 : DX, AX 파트별 충원 계획 ㄴ 인원계획 최종안 수립 및 충원계획 결재 *2025년도 인사평가 (FW) : 경영관리본부 요청 시 F/U | G3: 조직운영 ㄴ 2025년 팀 평가 제출 (팀원 3명, 팀장 1명) 보고 및 결정 사항 ㄴ 인원계획 대표님 의사결정에 따른 최종안 작성 및 결재 ㄴ KPI 설정 방식 및 기준 - 대표님 협의 및 최종안 결정
A4: =VLOOKUP(B4,기준값설정!$D$2:$E$22,2,FALSE) -> DX | B4: 정우철 | C4: 팀공통 | D4: =VLOOKUP(C4,기준값설정!$A$2:$B$22,2,FALSE) -> 공통2500 | E4: [한양대 치매코호트 용역] *사업 진행 여부 및 방향 협의 (2.23 월) ㄴ 사업범위 : 유지보수, 25년도 미구현사항 및 이슈해결, AI 서비스 연결 | F4: [한양대 치매코호트 용역] *사업계약 준비 ㄴ 세부 수행 범위 및 소요 비용산정(인건비 + 시스템 유지비용) | G4: 요청사항 - 25년도 업무 관련자 협의 필요 ㄴ 2025년도 진행사항에 대한 인수인계 ㄴ 2025년 계약서, 견적서, 협의사항 및 구현 산출물(기획서 등)
A5: =VLOOKUP(B5,기준값설정!$D$2:$E$22,2,FALSE) -> DX | B5: 정우철 | C5: 팀공통 | D5: =VLOOKUP(C5,기준값설정!$A$2:$B$22,2,FALSE) -> 공통2500 | E5: [제주대학교 임상실증 용역] *사업 수행 계약 준비 (지연) ㄴ 사업수행 범위 및 견적 작성 : 예상 견정 4000만원 이내 | F5: [제주대학교 임상실증 용역] *사업 수행 계약 준비 ㄴ 사업수행 범위 및 견적 : (진행) | G5: 진행 논의사항 요약 ㄴ 견적금약 4000만원 진행예정 ㄴ 계약 수주 및 견적 작성 지원 필요 (To WHO) AI Agent 개발 도구 라이센스 - Claude Code MAX 라이센스 1개 월 100$ 승인 검토
A6: =VLOOKUP(B6,기준값설정!$D$2:$E$22,2,FALSE) -> DX | B6: 정우철 | C6: 팀공통 | D6: =VLOOKUP(C6,기준값설정!$A$2:$B$22,2,FALSE) -> 공통2500 | E6: [보건복지부 글로벌 지원사업 - 지원 ] - 3월 10일 18:00 전자메일 제출 *사업계획서 작성 : 엘로디 초안 검토 및 조정 (정우철) * 과제 행정 및 제출서류 : 권현하 | F6: [보건복지부 글로벌 지원사업 - 지원 ] *사업계획서 작성 : 엘로디 초안 검토 및 수정 (정우철) * 과제 행정 및 제출서류 : 권현하 | G6: 수행일정 ㄴ 사업계획서 수정 작업 1차버전 : 3.6 금 까지
A7: =VLOOKUP(B7,기준값설정!$D$2:$E$22,2,FALSE) -> DX | B7: 정우철 | C7: 가상병원용인 | D7: =VLOOKUP(C7,기준값설정!$A$2:$B$22,2,FALSE) -> 과제0023 | E7: [시스템 실증] *가상병원 시스템 운영 전환 (2.10 화) ㄴ 운영전환 및 이슈사항 대용 - 시스템 모니터링 (외래 최적화 API 사용량 전달) | F7: [시스템 실증] *가상병원 시스템 운영 모니터링 및 지원 (~ 계속)
A8: =VLOOKUP(B8,기준값설정!$D$2:$E$22,2,FALSE) -> DX | B8: 정우철 | C8: 가상병원용인 | D8: =VLOOKUP(C8,기준값설정!$A$2:$B$22,2,FALSE) -> 과제0023 | E8: [2단계 1차년도 수행목표] *2단계 1차년도 : 기구축 시스템 실증 고도화 방향 검토 | F8: [2단계 1차년도 수행목표] * 외래 밀집도 검증 및 고도화 ㄴ 26년도 수행 Action Plan 수립 * 대시보드통합 및 프로세스마이닝 협의 (3월 11일 예정) ㄴ 관련 논의사항에 대한 내부 협의
A9: =VLOOKUP(B9,기준값설정!$D$2:$E$22,2,FALSE) -> DX | B9: 정우철 | C9: 비대면과제 | D9: =VLOOKUP(C9,기준값설정!$A$2:$B$22,2,FALSE) -> 과제0024 | E9: [웨어러블 의료기기 로지스틱 개발] * 요구사항 분석 - IA 작성 방법 논의 * 과제 수행 관련 회의: 2.24 화 W 스카이랩스 ㄴ 환자할당해제 : 스카이랩스에서 자체적으로 수행 ㄴ 로직스틱 개발 적용 방안 : 별도 개발 메뉴선택 시 Iframe로 적용 * 일산병원 요구사항협의 일정 ㄴ (일정변경) 3월초 -> 별도일정 (일산에서 전달예정 | F9: [웨어러블 의료기기 로지스틱 개발] * 요구사항 분석 - IA 리뷰 (데이터항목정의서, 기능명세서) * 일산병원 요구사항협의 일정 ㄴ 일정 확정 후 진행 예정
A10: =VLOOKUP(B10,기준값설정!$D$2:$E$22,2,FALSE) -> DX | B10: 이성전 | C10: 질병관리청 AX | D10: =VLOOKUP(C10,기준값설정!$A$2:$B$22,2,FALSE) -> 과제0027 | E10: [공통] * 통합 시스템 구축 ㄴ GPU 서버의 학습기간 동안 코로케이션 서비스 검토 ㄴ KT IDC 코로케이션 서비스 비용 확인 --> 198만원/월, 6개월 ㄴ 위험평가 WEB/WAS 서버의 SaaS 이용 검토 --> 검토 진행 중, 비용확인 예정 [방역용 AI 어시스턴트] * 1339 콜센터 상담 데이터 수집 ㄴ 개인정보 비식별 자료에 대한 법률검토 논의 (w/ 홍성표 대표님) [역학조사 고도화] * 요구기능 수집 및 검토/협의 | F10: [공통] * 통합 시스템 구축 ㄴ 시스템 구성 협의/조정 [방역용 AI 어시스턴트] * 1339 콜센터 상담 데이터 수집 ㄴ 개인정보 비식별 자료 선별 사용에 대한 법률 검토 * 챗봇 학습 데이터 사이트 연계 방안 논의 [역학조사 고도화] * 요구기능 수집 및 검토/협의(계속)
A11: =VLOOKUP(B11,기준값설정!$D$2:$E$22,2,FALSE) -> DX | B11: 이성전 | C11: 팀공통 | D11: =VLOOKUP(C11,기준값설정!$A$2:$B$22,2,FALSE) -> 공통2500 | E11: [모바일팀 인수인계 ] * 업무 지원 [AX Sprint 스마트 노인요양시설 표준모델] * 컨소시엄 구성 조건 업데이트 ㄴ 2개소 이상 요양시설 필요 ㄴ 장기요양시설은 공공 또는 비영리, 100인 이상 [제주대학교 분산형 임상시험 솔루션 구축] * N/A | F11: [모바일팀 인수인계 ] * 개발 소스코드 인수인계 진행 [AX Sprint 스마트 노인요양시설 표준모델] * 컨소시엄 구성 관련 업무협의 [제주대학교 분산형 임상시험 솔루션 구축] * 문의응대
A12: =VLOOKUP(B12,기준값설정!$D$2:$E$22,2,FALSE) -> DX | B12: 김영상 | C12: 팀공통 | D12: =VLOOKUP(C12,기준값설정!$A$2:$B$22,2,FALSE) -> 공통2500 | E12: [조직운영관리] *02/23(월) 오후 2시 2025년도 인사평가 면담 진행
A13: =VLOOKUP(B13,기준값설정!$D$2:$E$22,2,FALSE) -> DX | B13: 김영상 | C13: 팀공통 | D13: =VLOOKUP(C13,기준값설정!$A$2:$B$22,2,FALSE) -> 공통2500 | E13: [지식재산권] *"병상디스플레이 기능" 특허 일반 출원 진행 (약 4주 소요 예상) | F13: [지식재산권] *"병상디스플레이 기능" 특허 출원 진행
A14: =VLOOKUP(B14,기준값설정!$D$2:$E$22,2,FALSE) -> DX | B14: 김영상 | C14: 5G 1세부(현장수요) | D14: =VLOOKUP(C14,기준값설정!$A$2:$B$22,2,FALSE) -> 과제0013 | E14: [실증 준비] * 02/24(화) 신광 방문 : 서버 재기동 및 설정 지원 > 환자 연동 확인 | F14: [실증 준비] * 전광판 연동 상용 연동 Test 원격 지원 예정 * 하이젠 위치/Bed/이미지 연동 개발 Test 진행 예정
A15: =VLOOKUP(B15,기준값설정!$D$2:$E$22,2,FALSE) -> DX | B15: 김영상 | C15: 5G 1세부(현장수요) | D15: =VLOOKUP(C15,기준값설정!$A$2:$B$22,2,FALSE) -> 과제0013 | E15: [연구개발수행] * 네트워크 고도화 진행 관련 타업체 견적서 2개 추가 전달 완료 * 외부디스플레이 화면 기획 검토 : 02월 27일(금) 디자인 완료 예정 * 2026년 수행 목표 수립 | F15: [연구개발수행] * 외부 디스플레이 디자인 화면 검토 예정 * 2026년 수행 목표 수립 검토 회의 예정 | G15: 비용절감사항 ㄴ 네트워크 고도화 비용 : 주관에서 집행 결정 ㄴ 600만원 (정부지원금 대비 10+ %)
A16: =VLOOKUP(B16,기준값설정!$D$2:$E$22,2,FALSE) -> DX | B16: 김영상 | C16: AI영상검사 | D16: 과제0011 | E16: - | F16: [AI MRI Test] * 개선 개발 사항 Test
A17: DX | B17: 김영상 | C17: 가상병원_한림(2025년) | D17: HAX-의료-25004 | E17: [연구개발수행] * 2026년 수행 목표 수립 | F17: [연구개발수행] * 03/03일(화) 2026년 수행 목표 수립 검토 회의 [일산병원] * 03/04일(수) 자산고도화 2차 배포 예정
A18: DX | B18: 권현하 | C18: 해외진출지원 | D18: - | E18: [신규과제준비] * 사업계획서 작성 관련 규정 및 예산 검토(보산진 문의) ㄴ 외부용역기업 기준, 발표 관련, 예산 사용 기준 등 * 제출 서류 작성 | F18: [신규과제준비] * 사업비 비목 및 인건비 검토 * 제출 서류 준비완료
A19: DX | B19: 권현하 | C19: 비대면과제 | D19: 과제0024 | E19: [연구개발] - 웨어러블 로지스틱 관리 * 스카이랩스: 환자-장비 연동 방안 회의 진행(2/24) * 일산병원 요구사항 및 인터뷰 분석서(질의서) 기반 협의 일자 검토중 * 요구사항 및 분석 항목 구체화 | F19: [연구개발] - 웨어러블 로지스틱 관리 * 일산병원 요구사항 및 인터뷰 분석서(질의서) 기반 미팅 확정 * 요구사항 및 분석 항목 구체화
A20: DX | B20: 권현하 | C20: IoMT과제 | D20: 과제0024 | E20: [성과 검토] * 성과활용보고서 제출을 위한 2025년 성과 발생 현황 검토 | F20: [성과 검토] * 성과물 발생시 성과 등록 예정
A21: DX | B21: 권현하 | C21: 5G 3세부(재난현장) | D21: 과제0024 | E21: [RCMS] * 사업비 집행 중지 상태 검토 | F21: [RCMS] * 사업비 집행 중지 상태 검토 | G21: RCMS 연구비 집행 중지상태 - RCMS 민간부담금 납부 일자 오류로 미입금 처리됨 - 차년도 협약 완료 후 해결 가능
A22: DX | B22: 권현하 | C22: NIPA(공공AX) | D22: 과제0026 | E22: [협약 완료 및 사업비 신청] * 협약 완료 후 신규 과제코드 생성을 위한 공문 작성 * 1차 사업비 신청 서류 준비 | F22: [사업비 신청] - NIPA 협약 제출 관련 이슈 대응
A23: =VLOOKUP(B23,기준값설정!$D$2:$E$22,2,FALSE) -> AX | B23: 문선홍 | C23: AX공통 | D23: =VLOOKUP(C23,기준값설정!$A$2:$B$22,2,FALSE) -> 공통2500 | E23: [2025년도 평가 및 2026년 KPI 수립] * (완료) 2025년도 평가 : 1차 평가 (송하은, 최혜주) * (진행중) 2026년도 AX 파트 KPI 수립 | F23: [2025년도 평가 및 2026년 KPI 수립] * (완료예정) 2026년도 AX 파트 KPI 수립
A24: =VLOOKUP(B24,기준값설정!$D$2:$E$22,2,FALSE) -> AX | B24: 문선홍 | C24: AX공통 | D24: =VLOOKUP(C24,기준값설정!$A$2:$B$22,2,FALSE) -> 공통2500 | E24: [2026년 개발 계획 수립] * (진행중) 질병 관리청 AX / 일산병원 스케일업팁스 개발 계획 수립 ㄴ (완료) AX 파트의 개발 계획 ㄴ (완료) '26년 AX 파트 인력 계획 ㄴ (지연) 필요 자원 (장비/인력) 수급 계획 및 일정 * (지연) 식약처 인증 계획 및 방안 | F24: [2026년 개발 계획 수립] * (완료예정) 질병 관리청 AX / 일산병원 스케일업팁스 개발 계획 수립 ㄴ (완료예정) 개인별 개발 계획 ㄴ (완료예정) 필요 자원 (장비/인력) 수급 계획 및 일정 * (진행예정) 식약처 인증 계획 및 방안
A25: =VLOOKUP(B25,기준값설정!$D$2:$E$22,2,FALSE) -> AX | B25: 문선홍 | C25: 스케일업팁스일산 | D25: =VLOOKUP(C25,기준값설정!$A$2:$B$22,2,FALSE) -> 과제0026 | E25: [과제관리] * 해당 없음 | F25: [과제관리] * 해당 없음
A26: =VLOOKUP(B26,기준값설정!$D$2:$E$22,2,FALSE) -> AX | B26: 문선홍 | C26: 스케일업팁스일산 | D26: =VLOOKUP(C26,기준값설정!$A$2:$B$22,2,FALSE) -> 과제0026 | E26: [의료 AI 서비스 기획] * (진행중) 서비스 컨셉 기획 : 주요기능 및 서비스 항목 정의 * (진행중) 요구사항 정의 : 서비스 요구 사항 초안 도출 * (완료) 학습데이터셋 : 공공데이터 데이터 수집 방안 수립 | F26: [의료 AI 서비스 기획] * (완료예정) 서비스 컨셉 기획 : 주요기능 및 서비스 항목 정의 (초안) * (완료예정) 요구사항 정의 : 서비스 요구 사항 초안 도출 * (완료예정) 학습데이터셋 : 수집 대상 데이터 스펙 정리 및 리뷰 | G26: - 일산병원과 요구사항 및 컨셉 리뷰 실무 회의 진행 예정
A27: =VLOOKUP(B27,기준값설정!$D$2:$E$22,2,FALSE) -> AX | B27: 문선홍 | C27: 질병관리청 AX | D27: =VLOOKUP(C27,기준값설정!$A$2:$B$22,2,FALSE) -> 과제0027 | E27: [과제관리] * (완료) 방역 어시스턴트 개발 계획 수립 (WBS, 2026년도) ㄴ 방역어시스턴트 시스템 설계 및 개발 계획 수립/리뷰 | F27: [과제관리] * (진행예정) 시스템 구성 및 개발 관련 협의 ㄴ PI와 협의 및 R&D 본부와의 협의
A28: =VLOOKUP(B28,기준값설정!$D$2:$E$22,2,FALSE) -> AX | B28: 김지환 | C28: 질병관리청 AX | D28: =VLOOKUP(C28,기준값설정!$A$2:$B$22,2,FALSE) -> 과제0027 | E28: [방역 어시스턴트] - 시연 준비 * (지속) 질병관리청 : 담당연구관의 테스트 → 결과에 대한 오류 및 기능 수정 ㄴ 오류 사항 없음 (2026.02.27 질병관리청 테스트) * (지속) 테스트 결과 피드백 대응 : 신규 건 발생 시 대응 ㄴ 해당 사항 없음 * (완료) 방역어시스턴트 시연 준비 요구 자료 제출 ㄴ 챗봇 개발 모식도 ㄴ 제약사항 보완 계획 ㄴ 학습데이터 현황 및 향후 고도화 계획 | F28: [방역 어시스턴트] - 시연 준비 * (지속) 질병관리청 : 담당연구관의 테스트 → 결과에 대한 오류 및 기능 수정 * (지속) 테스트 결과 피드백 대응 : 신규 건 발생 시 대응 | G28: - 질병관리청장님 향 시연 및 보고 : 26.03.13
A29: =VLOOKUP(B29,기준값설정!$D$2:$E$22,2,FALSE) -> AX | B29: 김지환 | C29: 질병관리청 AX | D29: =VLOOKUP(C29,기준값설정!$A$2:$B$22,2,FALSE) -> 과제0027 | E29: [방역 어시스턴트] - 문서셋 추가 자동화 * (보류) 향후 질병관리청과 협의 후 개발 진행 | F29: [방역 어시스턴트] - 문서셋 추가 자동화
A30: =VLOOKUP(B30,기준값설정!$D$2:$E$22,2,FALSE) -> AX | B30: 김지환 | C30: 질병관리청 AX | D30: =VLOOKUP(C30,기준값설정!$A$2:$B$22,2,FALSE) -> 과제0027 | E30: [역학조사] - 역학조사내 AI 기능 개발 * (지속) 세종지사의 요구 사항 정의 및 분석 진행에 대한 지원 * (보류) 전염병 접촉 N 네트워크 플로팅 방법 조사 (요구사항 및 기능 정의 이후 진행) | F30: [역학조사] - 역학조사내 AI 기능 개발 * (지속) 세종지사의 요구 사항 정의 및 분석 진행에 대한 지원
A31: =VLOOKUP(B31,기준값설정!$D$2:$E$22,2,FALSE) -> AX | B31: 김지환 | C31: 질병관리청 AX | D31: =VLOOKUP(C31,기준값설정!$A$2:$B$22,2,FALSE) -> 과제0027 | E31: [기타] - 과제 진행 협의 / 인프라 * (완료) 2026년도 개발 계획 수립 및 시스템 설계 * (완료) 국정원 보안정책 개선 자료 작성 / 제출 : 서비스 별 AI 모델 현황 조사 * (완료) 과기부 GPU 물량 조사 자료 작성 / 제출 (질병관리청 필요 자원) : 감염병 대응 AX 통합 시스템 개발을 위한 GPU 물량 산정 내역서 | F31: [기타] - 과제 진행 협의 / 인프라 * 해당 없음 | G31: - (참고)GPU 서버의 인프라 구성에 대한 방안 조사 : 클러스터/쿠버네티스 (Service, ConfigMap 등)
A32: =VLOOKUP(B32,기준값설정!$D$2:$E$22,2,FALSE) -> AX | B32: 김지환 | C32: 질병관리청 AX | D32: =VLOOKUP(C32,기준값설정!$A$2:$B$22,2,FALSE) -> 과제0027 | E32: [기타] - 모델 및 개발 내용 검토 * 해당 없음 | F32: [기타] - 모델 및 개발 내용 검토 * 소관 업무 분류기 결과 검토 : VIGReg을 적용함으로써 모델 붕괴 없이 학습하는 실험(주연구자: 송하은)의 결과 검토 * 임베딩 모델 결과 검토 : 인코더 온리 모델의 학습(주연구자: 최혜주) 결과에서 Epoch 별 통계 변화 분석 검토 * 추가 문서 변환 (OCR) 모델 결과 검토 : 파싱 단계별 정상 작동 체크, 최종 파싱 결과 정상 유니코드 여부 확인 스크립트 작성(주연구자: 정원희)의 검토
A33: =VLOOKUP(B33,기준값설정!$D$2:$E$22,2,FALSE) -> AX | B33: 김지환 | C33: 스케일업팁스일산 | D33: =VLOOKUP(C33,기준값설정!$A$2:$B$22,2,FALSE) -> 과제0026 | E33: [기타] - 과제 산출물 대응 (특허) * 해당 없음 | F33: [기타] - 과제 산출물 대응 (특허) * (진행예정) 특허 준비 | G33: 해외 출원 중인 특허에 대한 후속 특허(P250900, 인공지능을 기반으로 이종 기기의 측정 데이터를 보정하는 전자 장치의 동작 방법)
A34: =VLOOKUP(B34,기준값설정!$D$2:$E$22,2,FALSE) -> AX | B34: 송하은 | C34: 질병관리청 AX | D34: =VLOOKUP(C34,기준값설정!$A$2:$B$22,2,FALSE) -> 과제0027 | E34: [방역 어시스턴트] 질의 분류기 (소관 업무 분류) * (완료) 파라미터 튜닝의 학습 모델 학습 (VICReg + Epoch 400) * (완료) 파라미터 튜닝의 학습 모델 학습 결과 분석 (VICReg + Epoch 400 결과) ㄴ Accuracy 0.957 (기존과 유사) ㄴ학습 안정성 개선 확인 * (진행중) 학습 결과에 따른 파라미터 튜닝 및 재학습 (Epoch 100,000) ㄴ 학습 수렴도 확인 후 학습 중단 예정 | F34: [방역 어시스턴트] 질의 분류기 (소관 업무 분류) * (완료예정) 학습 결과에 따른 파라미터 튜닝 및 재학습 (VICReg + Epoch 100,000) * (완료예정) 파라미터 튜닝 및 재학습 결과 분석 (VICReg + Epoch 100,000) ㄴ 학습 수렴 확인된 결과를 기반으로 결과 분석
A35: =VLOOKUP(B35,기준값설정!$D$2:$E$22,2,FALSE) -> AX | B35: 송하은 | C35: 질병관리청 AX | D35: =VLOOKUP(C35,기준값설정!$A$2:$B$22,2,FALSE) -> 과제0027 | E35: [방역 어시스턴트] 타 파운데이션 모델 연구 * (완료) microGPT의 구조 연구 및 소스 분석 ㄴ 목적 : Decoder Only Model 기술 확보 및 사용 가능성 파악 ㄴ 결론 : 향후 필요 시 적용 | F35: [방역 어시스턴트] 타 파운데이션 모델 연구 * 해당 없음 | G35: LLM 모델 기술 연구
A36: =VLOOKUP(B36,기준값설정!$D$2:$E$22,2,FALSE) -> AX | B36: 최혜주 | C36: 질병관리청 AX | D36: =VLOOKUP(C36,기준값설정!$A$2:$B$22,2,FALSE) -> 과제0027 | E36: [방역 어시스턴트] RAG 용 임베딩 모델 개발 (질병도메인 특화) * (중단) 질병 도메인 데이터셋 Full Set 학습 ㄴ 모델 : QLoRA 기반 CPT ㄴ 학습 시스템 변경 : PC -> A100 서버, 서버 성능 변경에 따른 파라미터 변경/테스트 ㄴ 질병관리청 테스트로 학습 중단 (2026.02.27) | F36: [방역 어시스턴트] RAG 용 임베딩 모델 개발 (질병도메인 특화) * (진행예정) 질병 도메인 데이터셋 Full Set 학습 ㄴ 모델 : QLoRA 기반 CPT ㄴ 학습 재개 (질병관리청 테스트 이후 학습 재개) * (진행예정) 학습 결과 분석 (QLoRA 기반 CPT)
A37: =VLOOKUP(B37,기준값설정!$D$2:$E$22,2,FALSE) -> AX | B37: 최혜주 | C37: 질병관리청 AX | D37: =VLOOKUP(C37,기준값설정!$A$2:$B$22,2,FALSE) -> 과제0027 | E37: [방역 어시스턴트] Agent 개발 연구 (실시간 데이터 연동 기반) * (진행예정) LLM의 "Tool Calling" 활용 의료 대응 Agent (PoC) ㄴ 내용 : MCP 기반 Tool Calling 기능 구현 테스트 (External API 연계 등) ㄴ PoC 개발 사항 : 지역명 기반 병원 검색, 앱 내 동적 지도 삽입(외부 어플리케이션) | F37: [방역 어시스턴트] Agent 개발 연구 (실시간 데이터 연동 기반) * (완료예정) LLM의 "Tool Calling" 활용 의료 대응 Agent (PoC) ㄴ 내용 : MCP 기반 Tool Calling 기능 구현 테스트 (External API 연계 등) ㄴ PoC 개발 사항 : 개발 코드 리뷰 * (진행예정) 서비스 적용 방안 검토 | G37: - Tool Calling : 외부 도구 (함수·API·데이터베이스 ·계산기 등)를 직접 호출해 실행하고 그 결과를 활용하는 기능
A38: =VLOOKUP(B38,기준값설정!$D$2:$E$22,2,FALSE) -> AX | B38: 최혜주 | C38: 스케일업팁스일산 | D38: =VLOOKUP(C38,기준값설정!$A$2:$B$22,2,FALSE) -> 과제0026 | E38: [기타] 모델 개선을 위한 알고리즘 연구 * (진행중) REACT: SYNERGIZING REASONING AND ACTING IN LANGUAGE MODELS 논문 리서치 및 내부 공유 | F38: [기타] 모델 개선을 위한 알고리즘 연구 * (완료예정) REACT: SYNERGIZING REASONING AND ACTING IN LANGUAGE MODELS 논문 리서치 및 내부 공유 | G38: - ReAct : 추론(reasoning)과 행동(acting) 능력을 하나로 결합하는 방법에 대한 연구 항목임 → 환각 해소와 추론 원인 해석의 효과
A39: =VLOOKUP(B39,기준값설정!$D$2:$E$22,2,FALSE) -> AX | B39: 정원희 | C39: 질병관리청 AX | D39: =VLOOKUP(C39,기준값설정!$A$2:$B$22,2,FALSE) -> 과제0027 | E39: [방역 어시스턴트] 학습데이터 생성 * (진행중) 질병관리청 제공 PDF의 텍스트 추출 OCR 모델 개발 ㄴ (완료) PdfToText 모듈 확장 : 텍스트 객체 추출 가능성 여부 판별 기능 구현 ㄴ 이미지 객체 배제, 도표의 일부분 인식, 텍스트 인식 | F39: [방역 어시스턴트] 학습데이터 생성 * (진행예정) 질병관리청 제공 PDF의 텍스트 추출 OCR 모델 개발 ㄴ 수정 후 구현 기능 문서화 : 사용 라이브러리/PDF 구조 정리 ㄴ 디코딩 실패한 텍스트 제거 기능 추가 ㄴ 디코딩 성공률 95% 미만 문서는 VLM으로 파싱하는 스크립트 정의
A40: =VLOOKUP(B40,기준값설정!$D$2:$E$22,2,FALSE) -> #N/A | D40: =VLOOKUP(C40,기준값설정!$A$2:$B$22,2,FALSE) -> #N/A
...

Sheet 20260213
A1: 파트 | B1: 성명 | C1: 프로젝트명 | D1: 프로젝트코드 | E1: 진행업무 | F1: 예정업무 | G1: 비고 및 이슈
A2: =VLOOKUP(B2,기준값설정!$D$2:$E$22,2,FALSE) -> DX | B2: 정우철 | C2: 팀공통 | D2: =VLOOKUP(C2,기준값설정!$A$2:$B$22,2,FALSE) -> 공통2500 | E2: [과제 수주 및 관리] *정량적, 정성적 목표 세부사항 정리 ㄴ 과제 통합 관리 템플릿 작성 및 세부사항 정리 (초안작성완료) | F2: [과제 수주 및 관리] *정량적, 정성적 목표 세부사항 정리 ㄴ 과제 통합 관리 템플릿 작성 및 세부사항 정리 (계속)
A3: =VLOOKUP(B3,기준값설정!$D$2:$E$22,2,FALSE) -> DX | B3: 정우철 | C3: 팀공통 | D3: =VLOOKUP(C3,기준값설정!$A$2:$B$22,2,FALSE) -> 공통2500 | E3: [제주대학교 임상실증 용역] *1차 업무 협의 컨퍼런스 콜 : 2.13 (금) W오재성 교수 ㄴ 기한 : 26년 7~8월, 예산 : 3000 + 알파 ㄴ P&T : 최소기능 수행견적, 제주대 : 산단 계약 진행 절차 확인 | F3: [제주대학교 임상실증 용역] *사업 수행 계약 준비 ㄴ 사업수행 범위 및 견적 작성 (예정) | G3: 진행 논의사항 요약 ㄴ 1차 핵심적인 기능 개발 위주로 진행 ㄴ 가용예산 : 3000만원 + 알파 ㄴ 구축기한 : 가능한 6월중
A4: =VLOOKUP(B4,기준값설정!$D$2:$E$22,2,FALSE) -> DX | B4: 정우철 | C4: 팀공통 | D4: =VLOOKUP(C4,기준값설정!$A$2:$B$22,2,FALSE) -> 공통2500 | E4: [조직운영관리] *2026년도 팀 목표 및 KPI 수립 방향 협의 ㄴ 팀/개인 KPI 수립 기준 및 평가기준 수립 (완료) ㄴ 팀 개인별 역량 평가 항목 및 기준 수립(완료) ㄴ 2026년도 팀 KPI 목표 수립(진행중) : 협의 (2.10 화 13:00 ~ ) *2025년도 인사평가 (진행중) : 대상 김영상차장 | F4: [조직운영관리] *2026년도 팀 목표 및 KPI 목표 수립 ㄴ 2026년도 팀 KPI 설정 방식 및 기준 작성 (예정) : 대표님 협의 사항 반영 *2026년도 인원계획 수립 : DX, AX 파트별 충원 계획 *2025년도 인사평가 (예정) : 대상 김영상차장 | G4: 보고 및 결정 사항 ㄴ 인원충원 계획 전달 예정 확인 의사결정 요청 ㄴ KPI 설정 방식 및 기준 (2월 내 1차 작성예정)
A5: =VLOOKUP(B5,기준값설정!$D$2:$E$22,2,FALSE) -> DX | B5: 정우철 | C5: 가상병원용인 | D5: =VLOOKUP(C5,기준값설정!$A$2:$B$22,2,FALSE) -> 과제0023 | E5: [시스템 실증] *가상병원 시스템 운영 전환 (2.10 화) ㄴ 운영전환 및 이슈사항 대용 - 시스템 모니터링 | F5: [시스템 실증] *가상병원 시스템 운영 전환 (2.10 화) ㄴ 운영전환 및 이슈사항 대용 - 시스템 모니터링
A6: =VLOOKUP(B6,기준값설정!$D$2:$E$22,2,FALSE) -> DX | B6: 정우철 | C6: 가상병원용인 | D6: =VLOOKUP(C6,기준값설정!$A$2:$B$22,2,FALSE) -> 과제0023 | E6: [2단계 1차년도 수행목표] *2단계 1차년도 수행 방안 오프라인 회의 (2.11 화) : 이효영, 정우철 참석예정 | F6: [2단계 1차년도 수행목표] *온라인정기회의 : 2.20 금
A7: =VLOOKUP(B7,기준값설정!$D$2:$E$22,2,FALSE) -> DX | B7: 정우철 | C7: 비대면과제 | D7: =VLOOKUP(C7,기준값설정!$A$2:$B$22,2,FALSE) -> 과제0024 | E7: [웨어러블 의료기기 로지스틱 개발] * 요구사항 분석 항목 및 인터뷰 질의서 리뷰 (W 권현하)
A8: =VLOOKUP(B8,기준값설정!$D$2:$E$22,2,FALSE) -> DX | B8: 정우철 | C8: 비대면과제 | D8: =VLOOKUP(C8,기준값설정!$A$2:$B$22,2,FALSE) -> 과제0024 | E8: [웨어러블 의료기기 환자 할당·해제 연동] * 논의 일정 수립 요청 : 스카이랩스 ㄴ 2월 24일 과제 수행 관련 협의 예정 | F8: [웨어러블 의료기기 환자 할당·해제 연동] * 스카이랩스 장비 연동 수행 방안 논의 (2.24) 예정
A9: =VLOOKUP(B9,기준값설정!$D$2:$E$22,2,FALSE) -> DX | B9: 이성전 | C9: 질병관리청 AX | D9: =VLOOKUP(C9,기준값설정!$A$2:$B$22,2,FALSE) -> 과제0027 | E9: [공통] * 통합 시스템 구축 ㄴ GPU 서버의 학습기간 동안 코로케이션 서비스 검토 ㄴ KT IDC 코로케이션 서비스 비용 확인 --> 198만원/월, 6개월 ㄴ 위험평가 WEB/WAS 서버의 SaaS 이용 검토 --> 검토 진행 중, 비용확인 예정 [방역용 AI 어시스턴트] * 1339 콜센터 상담 데이터 수집 ㄴ 개인정보 비식별 자료에 대한 법률검토 논의 (w/ 홍성표 대표님) [역학조사 고도화] * 요구기능 수집 및 검토/협의 | F9: [공통] * 통합 시스템 구축 ㄴ 시스템 구성 협의/조정 [방역용 AI 어시스턴트] * 1339 콜센터 상담 데이터 수집 ㄴ 개인정보 비식별 자료 선별 사용에 대한 법률 검토 * 챗봇 학습 데이터 사이트 연계 방안 논의 [역학조사 고도화] * 요구기능 수집 및 검토/협의(계속)
A10: =VLOOKUP(B10,기준값설정!$D$2:$E$22,2,FALSE) -> DX | B10: 이성전 | C10: 팀공통 | D10: =VLOOKUP(C10,기준값설정!$A$2:$B$22,2,FALSE) -> 공통2500 | E10: [모바일팀 인수인계 ] * 업무 지원 [AX Sprint 스마트 노인요양시설 표준모델] * 컨소시엄 구성 조건 업데이트 ㄴ 2개소 이상 요양시설 필요 ㄴ 장기요양시설은 공공 또는 비영리, 100인 이상 [제주대학교 분산형 임상시험 솔루션 구축] * N/A | F10: [모바일팀 인수인계 ] * 개발 소스코드 인수인계 진행 [AX Sprint 스마트 노인요양시설 표준모델] * 컨소시엄 구성 관련 업무협의 [제주대학교 분산형 임상시험 솔루션 구축] * 문의응대
A11: =VLOOKUP(B11,기준값설정!$D$2:$E$22,2,FALSE) -> DX | B11: 김영상 | C11: 팀공통 | D11: =VLOOKUP(C11,기준값설정!$A$2:$B$22,2,FALSE) -> 공통2500 | E11: [조직운영관리] *2025년도 인사평가 작성 완료 | F11: [조직운영관리] *02월23일 2층 대회의실 오후 3시 : 개인평가 면담 진행 예정
A12: =VLOOKUP(B12,기준값설정!$D$2:$E$22,2,FALSE) -> DX | B12: 김영상 | C12: 팀공통 | D12: =VLOOKUP(C12,기준값설정!$A$2:$B$22,2,FALSE) -> 공통2500 | E12: [지식재산권] *"병상디스플레이 기능" 특허 관련 "본" 업체 출원 내용 수정 후 전달 *특허 비용 집행 예정일 : 2026년 02월 13일(금) *"병상디스플레이 기능" 특허 일반 출원 진행 (약 4주 소요 예상) | F12: [지식재산권] *"병상디스플레이 기능" 특허 출원 진행
A13: =VLOOKUP(B13,기준값설정!$D$2:$E$22,2,FALSE) -> DX | B13: 김영상 | C13: 5G 1세부(현장수요) | D13: =VLOOKUP(C13,기준값설정!$A$2:$B$22,2,FALSE) -> 과제0013 | E13: [실증 준비] * 신광 방문 : 서버 재기동 및 설정 지원 > 환자 연동 확인 * Semi-Rpa 원격 불가 및 서버재기동시 간헐적으로 해당 서비스 미실행 상태 확인 | F13: [실증 준비] * 02월 24일(화) 신광 방문 후 상용 서버 설정 및 연동 Test 지원 예정
A14: =VLOOKUP(B14,기준값설정!$D$2:$E$22,2,FALSE) -> DX | B14: 김영상 | C14: 5G 1세부(현장수요) | D14: =VLOOKUP(C14,기준값설정!$A$2:$B$22,2,FALSE) -> 과제0013 | E14: [연구개발수행] * 전광판 상용 연동 일정 협의 : 설날 이후 진행 예정 * 네트워크 고도화 진행 여부 고려대병원 교수님께 검토 요청 * 외부디스플레이 화면 기획 검토 : 02월 27일(금) 디자인 완료 예정 * 2026년 수행 목표 수립 * 하이젠 환자 연동 관련 문의 사항 회의 진행 (김영상 차장, 이정택 주임) | F14: [연구개발수행] * 02월 26일(목) 전광판 상용 연동 Test 원격 지원 예정 * 하이젠 위치/환자 연동 추가 개발 기능 사내 Test 진행 예정 * 외부 디스플레이 디자인 화면 검토 예정 * 2026년 수행 목표 수립
A15: =VLOOKUP(B15,기준값설정!$D$2:$E$22,2,FALSE) -> DX | B15: 김영상 | C15: AI영상검사 | D15: 과제0011 | E15: [AI MRI 회의] *개선안 회의 : 문선홍 이사, 김영상 차장, 하태훈 선임, 강한별 대리, 전영민 사원 *개발 완료 예정일 : 3월 중순~말
A16: DX | B16: 김영상 | C16: 가상병원_한림(2025년) | D16: HAX-의료-25004 | E16: [연구개발수행] * 2026년 수행 목표 수립 [일산병원] * 자산고도화 2차 개발 사항 사내 Test 진행 | F16: [연구개발수행] * 2026년 수행 목표 수립 [일산병원] * 02/26일(목) 자산고도화 2차 배포 예정
A17: DX | B17: 권현하 | C17: 팀공통 | D17: 공통2500 | E17: [개발팀지원] * IoT장비 데이터 구조 파악을 위한 WMS, SH 시스템 가이드(2/11) ㄴ 자산 및 환자정보, 자산-환자 맵핑구조, 속성정보 등 | F17: [개발팀지원] * WMS, SH 시스템 파악
A18: DX | B18: 권현하 | C18: 비대면과제 | D18: 과제0024 | E18: [연구개발] - 웨어러블 로지스틱 관리 * 일산병원 요청사항 분석서(질의서) 작성 및 일산병원 전달 ㄴ 협의 일정 확정(2/24) | F18: [연구개발] - 웨어러블 로지스틱 관리 * 요구사항 인터뷰 분석서(질의서) 기반 일산병원 협의 진행 * 요구사항 및 분석 항목 구체화
A19: DX | B19: 권현하 | C19: 비대면과제 | D19: 과제0024 | E19: [정량정 성능 지표] * IRIS SW 저작권 성과 등록 완료 및 주관기관 내용 전달 | F19: [정량정 성능 지표] * 성과물 발생시 성과 등록 예정
A20: DX | B20: 권현하 | C20: 5G 3세부(재난현장) | D20: 과제0024 | E20: [과제행정] * RCMS 민간부담금 납부기한 변경 진행(주관기관 검토중) | F20: [과제행정] * RCMS 민간부담금 납부기한 변경 완료
A21: DX | B21: 권현하 | C21: 5G 3세부(재난현장) | D21: 과제0024 | E21: [연구비정산] * RCMS 정산 업무 수행 (경영지원실로부터 Back-up 지원) ㄴ 연구비사용시작을 위한 과제협약정보, 연구개발비 등 체크리스트 점검 ㄴ 연구개발비사용시작 처리 완료 | F21: [연구비정산] * RCMS 정산 이슈 대응
A22: DX | B22: 권현하 | C22: 스케일업팁스(단순중증) | D22: 과제0027 | E22: [과제행정] * 지급보증보험 서류 전담기관 제출 완료 | F22: [과제행정] * 이행(지급)보증보험 발행
A23: DX | B23: 권현하 | C23: NIPA(공공AX) | D23: 과제0026 | E23: [협약서류준비 및 제출] * 차년도 협약체결 준비를 위한 제출서류 검토 및 배포 * 협약서류제출 공문 작성(경영지원실로부터 Back-up 지원) * 제출서류 작성 및 인감 날인 완료 * 공동기관 협약서류 검토 및 보완 요청 완료 * 협약체결을 위한 NIPA 시스템 입력 및 서류 제출 완료 (NIPA 김윤하책임 문의) | F23: [협약서류준비] - NIPA 협약 제출 관련 이슈 대응
A24: =VLOOKUP(B24,기준값설정!$D$2:$E$22,2,FALSE) -> AX | B24: 문선홍 | C24: AX공통 | D24: =VLOOKUP(C24,기준값설정!$A$2:$B$22,2,FALSE) -> 공통2500 | E24: [2025년도 평가 및 2026년 KPI 수립] * (진행중) 2025년도 평가 : 자기 평가 자료 리뷰 및 면담, 1차평가 (송하은, 최혜주) * (완료) 2026년도 KPI 리뷰 | F24: [2025년도 평가 및 2026년 KPI 수립] * (완료예정) 2025년도 평가 : 1차 평가 (송하은, 최혜주) * (진행예정) 2026년도 AX 파트 KPI 수립
A25: =VLOOKUP(B25,기준값설정!$D$2:$E$22,2,FALSE) -> AX | B25: 문선홍 | C25: AX공통 | D25: =VLOOKUP(C25,기준값설정!$A$2:$B$22,2,FALSE) -> 공통2500 | E25: [2026년 개발 계획 수립] * (진행중) 질병 관리청 AX / 일산병원 스케일업팁스 개발 계획 수립 ㄴ AX 파트의 개발 계획 ㄴ 필요 자원 (장비/인력) 수급 계획 및 일정 ㄴ 식약처 인증 계획 및 방안 | F25: [2026년 개발 계획 수립] * (완료예정) 질병 관리청 AX / 일산병원 스케일업팁스 개발 계획 수립 ㄴ AX 파트의 개발 계획 ㄴ 필요 자원 (장비/인력) 수급 계획 및 일정 ㄴ 식약처 인증 계획 및 방안
A26: =VLOOKUP(B26,기준값설정!$D$2:$E$22,2,FALSE) -> AX | B26: 문선홍 | C26: 스케일업팁스일산 | D26: =VLOOKUP(C26,기준값설정!$A$2:$B$22,2,FALSE) -> 과제0026 | E26: [과제관리] * (완료) 2차년도 과제 진행 계획 수립 * (완료) 과제 진행 계획 협의 : 일산병원과 협의 (2026-02-12) | F26: 해당 없음
A27: =VLOOKUP(B27,기준값설정!$D$2:$E$22,2,FALSE) -> AX | B27: 문선홍 | C27: 스케일업팁스일산 | D27: =VLOOKUP(C27,기준값설정!$A$2:$B$22,2,FALSE) -> 과제0026 | E27: [의료 AI 서비스 기획] * (진행중) 서비스 컨셉 기획 : 주요기능 및 서비스 항목 정의 * (진행중) 요구사항 정의 : 서비스 요구 사항 초안 도출 | F27: [의료 AI 서비스 기획] * (진행예정) 서비스 컨셉 기획 : 주요기능 및 서비스 항목 정의 * (진행예정) 요구사항 정의 : 서비스 요구 사항 초안 도출
A28: =VLOOKUP(B28,기준값설정!$D$2:$E$22,2,FALSE) -> AX | B28: 문선홍 | C28: 질병관리청 AX | D28: =VLOOKUP(C28,기준값설정!$A$2:$B$22,2,FALSE) -> 과제0027 | E28: [과제관리] * (진행중) 방역 어시스턴트 개발 계획 수립 (WBS, 2026년도) | F28: [과제관리] * (진행예정) 방역 어시스턴트 개발 계획 수립 (WBS, 2026년도)
A29: =VLOOKUP(B29,기준값설정!$D$2:$E$22,2,FALSE) -> AX | B29: 김지환 | C29: 질병관리청 AX | D29: =VLOOKUP(C29,기준값설정!$A$2:$B$22,2,FALSE) -> 과제0027 | E29: [방역 어시스턴트] - 시연 준비 * (지속) 질병관리청 : 담당연구관의 테스트 → 결과에 대한 오류 및 기능 수정 * (완료) 테스트 결과 피드백 대응 : 잔여 1건 (완료), 신규 2건 (완료) ㄴ 잔여 (1건) : 쿼리에 대한 답변 변동/누락 (오류 수정) ㄴ 신규 (2건) : 참고문헌 번호 중복 제거 (기능 개선) , 참고문헌 번호 재정렬 (기능개선) | F29: [방역 어시스턴트] - 시연 준비 * (지속) 질병관리청 : 담당연구관의 테스트 → 결과에 대한 오류 및 기능 수정 * (지속) 테스트 결과 피드백 대응 : 신규 건 발생 시 대응
A30: =VLOOKUP(B30,기준값설정!$D$2:$E$22,2,FALSE) -> AX | B30: 김지환 | C30: 질병관리청 AX | D30: =VLOOKUP(C30,기준값설정!$A$2:$B$22,2,FALSE) -> 과제0027 | E30: [방역 어시스턴트] - 문서셋 추가 자동화 * (완료) 외부 문서 추가 요청에 대한 방안 수립 (질병관리청 요청) ㄴ 대상 사이트 : 공공포털, 질병청 사이트, 법령정보센터 ㄴ 연동 방식 : 크롤링, API 연동 * (완료) 외부 문서 추가 방식에 대한 테스트 : 테스트 결과 보고서 작성 | F30: [방역 어시스턴트] - 문서셋 추가 자동화 * (보류) 향후 질병관리청과 협의 후 개발 진행
A31: =VLOOKUP(B31,기준값설정!$D$2:$E$22,2,FALSE) -> AX | B31: 김지환 | C31: 질병관리청 AX | D31: =VLOOKUP(C31,기준값설정!$A$2:$B$22,2,FALSE) -> 과제0027 | E31: [역학조사] - 역학조사내 AI 기능 개발 * (완료) 역학조사의 요구사항 분석 건 리뷰 ㄴ 질병 관리청과 협의 : 2026-02-12 ㄴ 요구사항 대응 회의 (PnT 내부) : 2026-02-13 * (진행중) 전염병 접촉 N 네트워크 플로팅 방법 조사 | F31: [역학조사] - 역학조사내 AI 기능 개발 * (지속) 세종지사의 요구 사항 정의 및 분석 진행에 대한 지원 * (진행예정) 전염병 접촉 N 네트워크 플로팅 방법 조사
A32: =VLOOKUP(B32,기준값설정!$D$2:$E$22,2,FALSE) -> AX | B32: 김지환 | C32: 질병관리청 AX | D32: =VLOOKUP(C32,기준값설정!$A$2:$B$22,2,FALSE) -> 과제0027 | E32: [기타] - 과제 진행 협의 / 인프라 * (완료) 비대면 주간 회의 : 2026-02-12 * (완료) 보안성 검토 자료 작성 * (진행중) GPU 서버의 인프라 구성에 대한 방안 조사 : 클러스터/쿠버네티스 (ReplicaSet, Deployment, Service) * (진행중) 2026년도 개발 계획 수립 (WBS) | F32: [기타] - 과제 진행 협의 / 인프라 * (진행예정) GPU 서버의 인프라 구성에 대한 방안 조사 : 클러스터/쿠버네티스 (Service 등) * (진행예정) 2026년도 개발 계획 수립 (WBS)
A33: =VLOOKUP(B33,기준값설정!$D$2:$E$22,2,FALSE) -> AX | B33: 김지환 | C33: 스케일업팁스일산 | D33: =VLOOKUP(C33,기준값설정!$A$2:$B$22,2,FALSE) -> 과제0026 | E33: [기타] - 과제 산출물 대응 (특허) * (완료) 특허 문서 작성 : "이종 의료기기 사이의 측정값 분석 도구 개발" | G33: 해외 출원 중인 특허에 대한 후속 특허(P250900, 인공지능을 기반으로 이종 기기의 측정 데이터를 보정하는 전자 장치의 동작 방법)
A34: =VLOOKUP(B34,기준값설정!$D$2:$E$22,2,FALSE) -> AX | B34: 송하은 | C34: 질병관리청 AX | D34: =VLOOKUP(C34,기준값설정!$A$2:$B$22,2,FALSE) -> 과제0027 | E34: [방역 어시스턴트] 질의 분류기 (소관 업무 분류) * (완료) 학습 모델 개선 및 학습 결과 정리 * (완료) 학습 모델 개선 추가 요소 적용 개발 (프레임워크:VICReg/손실함수:SimCSE) * (완료) 학습 모델의 학습 결과 확인/리뷰 및 파라미터 튜닝 * (진행중) 파라미터 튜닝의 학습 모델 학습 (학습 진행중) | F34: [방역 어시스턴트] 질의 분류기 (소관 업무 분류) * (완료예정) 파라미터 튜닝의 학습 모델 학습 (학습완료 예정) * (완료예정) 파라미터 튜닝의 학습 모델 학습 결과 분석 * (진행예정) 학습 결과에 따른 파라미터 튜닝 및 재학습
A35: =VLOOKUP(B35,기준값설정!$D$2:$E$22,2,FALSE) -> AX | B35: 송하은 | C35: 질병관리청 AX | D35: =VLOOKUP(C35,기준값설정!$A$2:$B$22,2,FALSE) -> 과제0027 | E35: [방역 어시스턴트] 타 파운데이션 모델 연구 * (진행중) microGPT의 구조 연구 및 소스 분석 | F35: [방역 어시스턴트] 타 파운데이션 모델 연구 * (진행중) microGPT의 구조 연구 및 소스 분석 | G35: LLM 모델 기술 연구
A36: =VLOOKUP(B36,기준값설정!$D$2:$E$22,2,FALSE) -> AX | B36: 최혜주 | C36: 질병관리청 AX | D36: =VLOOKUP(C36,기준값설정!$A$2:$B$22,2,FALSE) -> 과제0027 | E36: [방역 어시스턴트] RAG 용 임베딩 모델 개발 (질병도메인 특화) * (완료) 질병도메인 특화 단어 확장모델 중간 평가(QLoRA 기반 CPT) ㄴ 기 모델(분할 데이터 학습) 대비 성능 향상 (Top-1 정확도, 0.2972 → 0.3134) * (진행중) 질병 도메인 데이터셋 미세조정 학습 (학습중) * (진행중) 미세조정된 학습 모델 평가 | F36: [방역 어시스턴트] RAG 용 임베딩 모델 개발 (질병도메인 특화) * (진행예정) 질병 도메인 데이터셋 미세조정 학습 (학습중) * (진행예정) 미세조정된 학습 모델 평가
A37: =VLOOKUP(B37,기준값설정!$D$2:$E$22,2,FALSE) -> AX | B37: 최혜주 | C37: 질병관리청 AX | D37: =VLOOKUP(C37,기준값설정!$A$2:$B$22,2,FALSE) -> 과제0027 | E37: [방역 어시스턴트] Agent 개발 연구 (실시간 데이터 연동 기반) * (진행중) LLM의 "Tool Calling" 활용 업무보조 도구 개발 (PoC) - 챗봇 앱 MCP (Model Context Protocol) 기반 - MCP 기반 Tool Calling 기능 구현 테스트 (응급처치방법, 병원검색 등) | F37: [방역 어시스턴트] Agent 개발 연구 (실시간 데이터 연동 기반) * (진행예정) LLM의 "Tool Calling" 활용 업무보조 도구 개발 (PoC) - MCP 기반 Tool Calling 기능 구현 테스트 (External API 연계 등) | G37: - Tool Calling : 외부 도구 (함수·API·데이터베이스 ·계산기 등)를 직접 호출해 실행하고 그 결과를 활용하는 기능
A38: =VLOOKUP(B38,기준값설정!$D$2:$E$22,2,FALSE) -> AX | B38: 최혜주 | C38: 스케일업팁스일산 | D38: =VLOOKUP(C38,기준값설정!$A$2:$B$22,2,FALSE) -> 과제0026 | E38: [기타] 모델 개선을 위한 알고리즘 연구 * (진행중) REACT: SYNERGIZING REASONING AND ACTING IN LANGUAGE MODELS 논문 리서치 | F38: [기타] 모델 개선을 위한 알고리즘 연구 * (완료예정) REACT: SYNERGIZING REASONING AND ACTING IN LANGUAGE MODELS 논문 리서치 및 내부 공유 | G38: - ReAct : 추론(reasoning)과 행동(acting) 능력을 하나로 결합하는 방법에 대한 연구 항목임 → 환각 해소와 추론 원인 해석의 효과
A39: =VLOOKUP(B39,기준값설정!$D$2:$E$22,2,FALSE) -> AX | B39: 정원희 | C39: 질병관리청 AX | D39: =VLOOKUP(C39,기준값설정!$A$2:$B$22,2,FALSE) -> 과제0027 | E39: [방역 어시스턴트] 학습데이터 생성 * (완료) 질병관리청 제공 PDF OCR 판별 기능 구현 * (진행중) 질병관리청 제공 PDF OCR 판별 기능 보완 및 수정 | F39: [방역 어시스턴트] 학습데이터 생성 * (완료예정) 질병관리청 제공 PDF OCR 판별 기능 보완 및 수정 * (진행예정) OCR 가능 PDF 분류 및 텍스트 추출
A40: =VLOOKUP(B40,기준값설정!$D$2:$E$22,2,FALSE) -> #N/A | D40: =VLOOKUP(C40,기준값설정!$A$2:$B$22,2,FALSE) -> #N/A
...

Sheet 20260206
A1: 파트 | B1: 성명 | C1: 프로젝트명 | D1: 프로젝트코드 | E1: 진행업무 | F1: 예정업무 | G1: 비고 및 이슈
A2: =VLOOKUP(B2,기준값설정!$D$2:$E$22,2,FALSE) -> DX | B2: 정우철 | C2: 팀공통 | D2: =VLOOKUP(C2,기준값설정!$A$2:$B$22,2,FALSE) -> 공통2500 | E2: [과제 수주 및 관리] *정량적, 정성적 목표 세부사항 정리 ㄴ 과제 통합 관리 템플릿 작성 및 세부사항 정리 (진행중) *과제별 수행 실무책임자 선정 및 수행 계획 및 목표 수립 ㄴ 팀 KPI 수립 시 작성 통합하여 작성 (항목 제외) *과제별 계속비 편성 및 기관부담금입금관련 점검 ㄴ 유연의료 3세부 부담금 입금 오류사항 조치중 | F2: [과제 수주 및 관리] *정량적, 정성적 목표 세부사항 정리 ㄴ 과제 통합 관리 템플릿 작성 및 세부사항 정리 (계속) *과제별 계속비 편성 및 기관부담금입금관련 점검 ㄴ 유연의료 3세부 부담금 입금 오류사항 조치중 | G2: * 유연의료 3세부 부담금관련 납부기한 이슈 ㄴ 협약내용 입금기한이 RCMS에 반영되지 않음 ㄴ 주관기관 통하여 조치방안 확인 중
A3: =VLOOKUP(B3,기준값설정!$D$2:$E$22,2,FALSE) -> DX | B3: 정우철 | C3: 팀공통 | D3: =VLOOKUP(C3,기준값설정!$A$2:$B$22,2,FALSE) -> 공통2500 | E3: [조직운영관리] *2026년도 팀 목표 및 KPI 수립 ㄴ 팀/개인 KPI 수립 기준 및 평가기준 수립 (진행중) ㄴ 팀 개인별 역량 평가 항목 및 기준 수립(진행중) ㄴ 2026년도 팀 KPI 목표 수립(진행중) *질병관리청 공공 AX - 실무책임자 교체 ㄴ (변경) 이성전 이사 | F3: [조직운영관리] *2026년도 팀 목표 및 KPI 목표 수립 ㄴ 팀/개인 KPI 수립 기준 및 평가기준 수립 (진행중) ㄴ 팀 개인별 역량 평가 항목 및 기준 수립(진행중) ㄴ 2026년도 팀 KPI 목표 수립(진행중) : 협의 (2.10 화 13:00 ~ ) *2025년도 인사평가 ㄴ 대상자 면담 및 평가기준 논의 | G3: *질병관리청 공공AX 실무책임자 변경 ㄴ 이성전 이사로 변경함 *한양대 치매코호트 과제 용역 진행방안 ㄴ 수행방안 결정 및 KPI 목표 논의 시 방향 결정(예정)
A4: =VLOOKUP(B4,기준값설정!$D$2:$E$22,2,FALSE) -> DX | B4: 정우철 | C4: 팀공통 | D4: =VLOOKUP(C4,기준값설정!$A$2:$B$22,2,FALSE) -> 공통2500 | E4: [지식재산권] *병상정보디스플레이 활용 IoT 장치데이터 수집 ㄴ 발명신고서 기안 및 승인 (완료) ㄴ 자금집행 및 출원 진행 요청 (T. 장복주) | F4: [지식재산권] *병상정보디스플레이 활용 IoT 장치데이터 수집 ㄴ 출원내용 보강 및
A5: =VLOOKUP(B5,기준값설정!$D$2:$E$22,2,FALSE) -> DX | B5: 정우철 | C5: 가상병원용인 | D5: =VLOOKUP(C5,기준값설정!$A$2:$B$22,2,FALSE) -> 과제0023 | E5: [시스템 실증] *가상병원 시스템 운영 전환 준비 ㄴ 채혈실 밀집도 및 외래최적화 서비스 설정변경 기능수정사항 및 배포 | F5: [시스템 실증] *가상병원 시스템 운영 전환 (2.10 화) ㄴ 운영전환 및 이슈사항 대용 - 시스템 모니터링 | G5: * 가상병원 운영 전환 : 2.10 화 ㄴ 오픈 후 상태 모니터링 및 점검 예정
A6: =VLOOKUP(B6,기준값설정!$D$2:$E$22,2,FALSE) -> DX | B6: 정우철 | C6: 가상병원용인 | D6: =VLOOKUP(C6,기준값설정!$A$2:$B$22,2,FALSE) -> 과제0023 | F6: [2단계 1차년도 수행목표] *2단계 1차년도 수행 방안 오프라인 회의 (2.11 화) : 이효영, 정우철 참석예정 | G6: * 가상병원 수행방안 협의 : 2.11 수 ㄴ 용인, 양산부산대, 헬리오센, 피플앤드테크놀러지
A7: =VLOOKUP(B7,기준값설정!$D$2:$E$22,2,FALSE) -> DX | B7: 정우철 | C7: 5G 1세부(현장수요) | D7: =VLOOKUP(C7,기준값설정!$A$2:$B$22,2,FALSE) -> 과제0013 | E7: [단계평가] * 1단계 단계평가 준비 및 평가 (02.04 수)
A8: =VLOOKUP(B8,기준값설정!$D$2:$E$22,2,FALSE) -> DX | B8: 정우철 | C8: 5G 3세부(재난현장) | D8: =VLOOKUP(C8,기준값설정!$A$2:$B$22,2,FALSE) -> 과제0014 | E8: [단계평가] * 1단계 단계평가 준비 및 평가 (02.04 수)
A9: =VLOOKUP(B9,기준값설정!$D$2:$E$22,2,FALSE) -> DX | B9: 정우철 | C9: 비대면과제 | D9: =VLOOKUP(C9,기준값설정!$A$2:$B$22,2,FALSE) -> 과제0024 | E9: [웨어러블 의료기기 로지스틱 개발] * 요구사항 분석 항목 및 인터뷰 질의서 리뷰 (W 권현하) | F9: [웨어러블 의료기기 로지스틱 개발] * 요구사항 분석 항목 및 인터뷰 질의서 리뷰 (W 권현하) * 요구사항 구체화를 위한 협의 진행 (예정)
A10: =VLOOKUP(B10,기준값설정!$D$2:$E$22,2,FALSE) -> DX | B10: 정우철 | C10: 비대면과제 | D10: =VLOOKUP(C10,기준값설정!$A$2:$B$22,2,FALSE) -> 과제0024 | E10: [웨어러블 의료기기 환자 할당·해제 연동] * 논의 일정 수립 요청 (T 스카이랩스) | F10: [웨어러블 의료기기 환자 할당·해제 연동] * 스카이랩스 장비 연동 - 현황파악 및 수행방안 논의 (예정)
A11: =VLOOKUP(B11,기준값설정!$D$2:$E$22,2,FALSE) -> DX | B11: 이성전 | C11: 질병관리청 AX | D11: =VLOOKUP(C11,기준값설정!$A$2:$B$22,2,FALSE) -> 과제0027 | E11: [인수인계 및 현황파악] * 사업계획서 및 진행사항 파악 | F11: [인수인계 및 현황파악] * 사업계획서 및 진행사항 파악(계속) * 정기 주간회의
A12: =VLOOKUP(B12,기준값설정!$D$2:$E$22,2,FALSE) -> DX | B12: 이성전 | C12: 팀공통 | D12: =VLOOKUP(C12,기준값설정!$A$2:$B$22,2,FALSE) -> 공통2500 | E12: [모바일팀 인수인계 ] * 이성전 -> 이효영 * 각 사업별 진행사항 및 인사 자료 전달 * 업무협의 및 지원 | F12: [모바일팀 인수인계 ] * 업무협의 및 지원 * 25년 귀속 인사평가 개별 면담(예정)
A13: =VLOOKUP(B13,기준값설정!$D$2:$E$22,2,FALSE) -> DX | B13: 이성전 | C13: 팀공통 | D13: =VLOOKUP(C13,기준값설정!$A$2:$B$22,2,FALSE) -> 공통2500 | E13: [AX Sprint 스마트 노인요양시설 표준모델] - 제안 준비 (Holding): 2월말 정식 공고예정 | F13: [AX Sprint 스마트 노인요양시설 표준모델] - N/A
A14: =VLOOKUP(B14,기준값설정!$D$2:$E$22,2,FALSE) -> DX | B14: 김영상 | C14: DX공통 | D14: =VLOOKUP(C14,기준값설정!$A$2:$B$22,2,FALSE) -> 공통2500 | E14: [지식재산권] *"병상디스플레이 기능" 특허 관련 "본" 업체 출원 진행 문의 * 특허 출원 제10-2023-0049003호에 대한 등록비용 청구 요청 (장복주 부장) | F14: [지식재산권] *"병상디스플레이 기능" 특허 출원 예정
A15: =VLOOKUP(B15,기준값설정!$D$2:$E$22,2,FALSE) -> DX | B15: 김영상 | C15: 5G 1세부(현장수요) | D15: =VLOOKUP(C15,기준값설정!$A$2:$B$22,2,FALSE) -> 과제0013 | E15: [단계평가준비] * 1단계 단계평가 준비 (02.04 수)
A16: =VLOOKUP(B16,기준값설정!$D$2:$E$22,2,FALSE) -> DX | B16: 김영상 | C16: 5G 1세부(현장수요) | D16: =VLOOKUP(C16,기준값설정!$A$2:$B$22,2,FALSE) -> 과제0013 | E16: [연구개발수행] * 외부디스플레이 화면 기획에 따른 기능/디자인(곽태정 대리) 검토 * 네트워크 고도화 비용 집행에 따른 결재 | F16: [연구개발수행] * 전광판 상용 연동 일정 협의 예정 * 네트워크 고도화 일정 협의 예정
A17: =VLOOKUP(B17,기준값설정!$D$2:$E$22,2,FALSE) -> DX | B17: 김영상 | C17: 5G 3세부(재난현장) | D17: =VLOOKUP(C17,기준값설정!$A$2:$B$22,2,FALSE) -> 과제0014 | E17: [단계평가준비] * 1단계 단계평가 준비 (02.04 수)
A18: =VLOOKUP(B18,기준값설정!$D$2:$E$22,2,FALSE) -> DX | B18: 권현하 | C18: 5G 3세부(재난현장) | D18: =VLOOKUP(C18,기준값설정!$A$2:$B$22,2,FALSE) -> 과제0014 | E18: [과제행정] * RCMS 민간부담금 납부기한 변경 진행중 ㄴ 주관기관에게 변경 요청 | F18: [과제행정] * 민간부담금 납부기한 변경 완료
A19: =VLOOKUP(B19,기준값설정!$D$2:$E$22,2,FALSE) -> DX | B19: 권현하 | C19: 팀공통 | D19: =VLOOKUP(C19,기준값설정!$A$2:$B$22,2,FALSE) -> 공통2500 | E19: [과제행정] * 과제 계속비 편성 및 기관부담금 입금 관련 정보 문의 * 전체 수행과제 현황 파악 ㄴ 과제별 간사, 연구관리시스템 정보 | F19: [과제행정] * 과제 수행 이슈 대응
A20: =VLOOKUP(B20,기준값설정!$D$2:$E$22,2,FALSE) -> DX | B20: 권현하 | C20: 비대면과제 | D20: =VLOOKUP(C20,기준값설정!$A$2:$B$22,2,FALSE) -> 과제0024 | E20: [연구개발] - 웨어러블 로지스틱 관리 * 일산병원 요청사항 분석서 초안 작성 및 1차 검토 | F20: [연구개발] - 웨어러블 로지스틱 관리 * 시스템 요구사항 검토 및 분석 ㄴ 인터뷰 질의서 작성
A21: =VLOOKUP(B21,기준값설정!$D$2:$E$22,2,FALSE) -> DX | B21: 권현하 | C21: 비대면과제 | D21: =VLOOKUP(C21,기준값설정!$A$2:$B$22,2,FALSE) -> 과제0024 | E21: [정량정 성능 지표] * IRIS SW 저작권 등록을 위한 정보 요청 | F21: [정량정 성능 지표] * IRIS SW 저작권 등록 완료 및 주관기관 내용 전달
A22: =VLOOKUP(B22,기준값설정!$D$2:$E$22,2,FALSE) -> #N/A | D22: =VLOOKUP(C22,기준값설정!$A$2:$B$22,2,FALSE) -> #N/A
A23: =VLOOKUP(B23,기준값설정!$D$2:$E$22,2,FALSE) -> #N/A | D23: =VLOOKUP(C23,기준값설정!$A$2:$B$22,2,FALSE) -> #N/A
A24: =VLOOKUP(B24,기준값설정!$D$2:$E$22,2,FALSE) -> #N/A | D24: =VLOOKUP(C24,기준값설정!$A$2:$B$22,2,FALSE) -> #N/A
A25: =VLOOKUP(B25,기준값설정!$D$2:$E$22,2,FALSE) -> #N/A | D25: =VLOOKUP(C25,기준값설정!$A$2:$B$22,2,FALSE) -> #N/A
A26: =VLOOKUP(B26,기준값설정!$D$2:$E$22,2,FALSE) -> #N/A | D26: =VLOOKUP(C26,기준값설정!$A$2:$B$22,2,FALSE) -> #N/A
A27: =VLOOKUP(B27,기준값설정!$D$2:$E$22,2,FALSE) -> #N/A | D27: =VLOOKUP(C27,기준값설정!$A$2:$B$22,2,FALSE) -> #N/A
A28: =VLOOKUP(B28,기준값설정!$D$2:$E$22,2,FALSE) -> #N/A | D28: =VLOOKUP(C28,기준값설정!$A$2:$B$22,2,FALSE) -> #N/A
A29: =VLOOKUP(B29,기준값설정!$D$2:$E$22,2,FALSE) -> #N/A | D29: =VLOOKUP(C29,기준값설정!$A$2:$B$22,2,FALSE) -> #N/A
A30: =VLOOKUP(B30,기준값설정!$D$2:$E$22,2,FALSE) -> #N/A | D30: =VLOOKUP(C30,기준값설정!$A$2:$B$22,2,FALSE) -> #N/A
A31: =VLOOKUP(B31,기준값설정!$D$2:$E$22,2,FALSE) -> #N/A | D31: =VLOOKUP(C31,기준값설정!$A$2:$B$22,2,FALSE) -> #N/A
A32: =VLOOKUP(B32,기준값설정!$D$2:$E$22,2,FALSE) -> #N/A | D32: =VLOOKUP(C32,기준값설정!$A$2:$B$22,2,FALSE) -> #N/A
A33: =VLOOKUP(B33,기준값설정!$D$2:$E$22,2,FALSE) -> #N/A | D33: =VLOOKUP(C33,기준값설정!$A$2:$B$22,2,FALSE) -> #N/A

Sheet 20260206_DX
A1: 프로젝트명 | B1: 프로젝트코드 | C1: 진행업무 | D1: 예정업무 | E1: 비고 및 이슈
A2: 팀공통 | B2: =VLOOKUP(A2,기준값설정!$A$2:$B$22,2,FALSE) -> 공통2500 | C2: [과제 수주 및 관리] * (사업계획) AX Sprint 스마트 노인요양시설 표준모델 ㄴ 제안 준비 (Holding): 정식공고 후 진행 예정 *정량적, 정성적 목표 세부사항 정리 ㄴ 과제 통합 관리 템플릿 작성 및 세부사항 정리 (진행중) *과제별 수행 실무책임자 선정 및 수행 계획 및 목표 수립 ㄴ 팀 KPI 수립 시 작성 통합하여 작성 (항목 제외) | D2: [과제 수주 및 관리] *정량적, 정성적 목표 세부사항 정리 ㄴ 과제 통합 관리 템플릿 작성 및 세부사항 정리 (계속) | E2: *과제사업계획 - 요양시설 (보류) ㄴ 정식 사업공고 후 진행
C3: [조직운영관리] *2026년도 팀 목표 및 KPI 수립 ㄴ 팀/개인 KPI 수립 기준 및 평가기준 수립 (진행중) ㄴ 팀 개인별 역량 평가 항목 및 기준 수립(진행중) ㄴ 2026년도 팀 KPI 목표 수립(진행중) | D3: [조직운영관리] *2026년도 팀 목표 및 KPI 목표 수립 ㄴ 팀/개인 KPI 수립 기준 및 평가기준 수립 (진행중) ㄴ 팀 개인별 역량 평가 항목 및 기준 수립(진행중) ㄴ 2026년도 팀 KPI 목표 수립(진행중) : 협의 (2.10 화 13:00 ~ ) *2025년도 인사평가 ㄴ 대상자 면담 및 자체평가 실시 | E3: *질병관리청 공공AX 실무책임자 변경 ㄴ 이성전 이사로 변경함 *한양대 치매코호트 과제 용역 진행방안 ㄴ 수행방안 결정 및 KPI 목표 논의 시 방향 결정(예정)
C4: [지식재산권] *병상정보디스플레이 활용 IoT 장치데이터 수집 출원 검토 (완료) ㄴ 발명신고서 기안 및 승인 (완료) * IoMT 동행자 특허 등록비용 청구 요청 (장복주 부장) | D4: [지식재산권] *"병상정보디스플레이 활용 IoT 장치데이터 수집" 출원 (진행) | E4: *병상정보디스플레이 활용 특허 출원 진행 ㄴ 경영지원실 출원 진행 자급 집행 요청
C5: [모바일팀 인수인계 ] 이성전 * 각 사업별 진행사항 및 인사 자료 전달 * 업무협의 및 지원 | D5: [모바일팀 인수인계 ] * 업무협의 및 지원 * 25년 귀속 인사평가 개별 면담(예정)
C6: [AX Sprint 스마트 노인요양시설 표준모델] - 제안 준비 (Holding): 2월말 정식 공고예정 | D6: [AX Sprint 스마트 노인요양시설 표준모델] - N/A | E6: *병상정보디스플레이 활용 특허 출원 진행 ㄴ 경영지원실 출원 진행 자급 집행 요청
C7: [과제행정] * 과제 계속비 편성 및 기관부담금 입금 관련 정보 문의 * 전체 수행과제 현황 파악 ㄴ 과제별 간사, 연구관리시스템 정보 | D7: [과제행정] * 과제 수행 이슈 대응
A8: DX공통 | B8: =VLOOKUP(A8,기준값설정!$A$2:$B$22,2,FALSE) -> 공통2500 | C8: [지식재산권] *"병상디스플레이 기능" 특허 관련 "본" 업체 출원 진행 문의 * 특허 출원 제10-2023-0049003호에 대한 등록비용 청구 요청 (장복주 부장) | D8: [지식재산권] *"병상디스플레이 기능" 특허 출원 예정
A9: 5G 1세부(현장수요) | B9: =VLOOKUP(A9,기준값설정!$A$2:$B$22,2,FALSE) -> 과제0013 | C9: [단계평가] * 1단계 단계평가 준비 및 평가 (02.04 수)
C10: [연구개발수행] * 외부디스플레이 화면 기획에 따른 기능/디자인(곽태정 대리) 검토 * 네트워크 고도화 비용 집행에 따른 결재 | D10: [연구개발수행] * 전광판 상용 연동 일정 협의 예정 * 네트워크 고도화 일정 협의 예정
A11: 5G 3세부(재난현장) | B11: =VLOOKUP(A11,기준값설정!$A$2:$B$22,2,FALSE) -> 과제0014 | C11: [단계평가] * 1단계 단계평가 준비 및 평가 (02.04 수)
C12: [과제행정] * RCMS 민간부담금 납부기한 변경 진행중 ㄴ 주관기관에게 변경 요청 | D12: [과제행정] * 민간부담금 납부기한 변경 완료 | E12: * 유연의료 3세부 부담금관련 납부기한 2.1일 설정 조치 ㄴ 협약내용 입금기한이 RCMS에 반영되지 않음 ㄴ 주관기관 통하여 조치방안 확인 중
A13: 가상병원용인 | B13: =VLOOKUP(A13,기준값설정!$A$2:$B$22,2,FALSE) -> 과제0023 | C13: [시스템 실증] *가상병원 시스템 운영 전환 준비 ㄴ 채혈실 밀집도 및 외래최적화 서비스 설정변경 기능수정사항 및 배포 | D13: [시스템 실증] *가상병원 시스템 운영 전환 (2.10 화) ㄴ 운영전환 및 이슈사항 대용 - 시스템 모니터링 | E13: * 가상병원 운영 전환 : 2.10 화 ㄴ 오픈 후 상태 모니터링 및 점검 예정
D14: [2단계 1차년도 수행목표] *2단계 1차년도 수행 방안 오프라인 회의 (2.11 화) : 이효영, 정우철 참석예정 | E14: * 가상병원 수행방안 협의 : 2.11 수 ㄴ 용인, 양산부산대, 헬리오센, 피플앤드테크놀러지
A15: 비대면과제 | B15: =VLOOKUP(A15,기준값설정!$A$2:$B$22,2,FALSE) -> 과제0024 | C15: [연구개발] - 웨어러블 로지스틱 관리 * 일산병원 요청사항 분석서 초안 작성 및 1차 검토 | D15: [연구개발] - 웨어러블 로지스틱 관리 * 시스템 요구사항 검토 및 분석 : 인터뷰 질의서 작성 | E15: * 권현하 대리 : 기획 업무 역량 강화 목적 배정
C16: [정량정 성능 지표] * IRIS SW 저작권 등록을 위한 정보 요청 | D16: [정량정 성능 지표] * IRIS SW 저작권 등록 완료 및 주관기관 내용 전달 | E16: * 25년 성과 미진행 사항 조치
A17: 질병관리청 AX | B17: =VLOOKUP(A17,기준값설정!$A$2:$B$22,2,FALSE) -> 과제0027 | C17: [인수인계 및 현황파악] * 사업계획서 및 진행사항 파악 | D17: [인수인계 및 현황파악] * 사업계획서 및 진행사항 파악(계속) * 정기 주간회의 | E17: * 실무 PM 교체 : 이성전이사
B18: =VLOOKUP(A18,기준값설정!$A$2:$B$22,2,FALSE) -> #N/A
B19: =VLOOKUP(A19,기준값설정!$A$2:$B$22,2,FALSE) -> #N/A
B20: =VLOOKUP(A20,기준값설정!$A$2:$B$22,2,FALSE) -> #N/A
B21: =VLOOKUP(A21,기준값설정!$A$2:$B$22,2,FALSE) -> #N/A
B22: =VLOOKUP(A22,기준값설정!$A$2:$B$22,2,FALSE) -> #N/A
B23: =VLOOKUP(A23,기준값설정!$A$2:$B$22,2,FALSE) -> #N/A
B24: =VLOOKUP(A24,기준값설정!$A$2:$B$22,2,FALSE) -> #N/A
B25: =VLOOKUP(A25,기준값설정!$A$2:$B$22,2,FALSE) -> #N/A
B26: =VLOOKUP(A26,기준값설정!$A$2:$B$22,2,FALSE) -> #N/A
B27: =VLOOKUP(A27,기준값설정!$A$2:$B$22,2,FALSE) -> #N/A
B28: =VLOOKUP(A28,기준값설정!$A$2:$B$22,2,FALSE) -> #N/A
B29: =VLOOKUP(A29,기준값설정!$A$2:$B$22,2,FALSE) -> #N/A

Sheet 작성예시
A1: 파트 | B1: 성명 | C1: 프로젝트명 | D1: 프로젝트코드 | E1: 진행업무 | F1: 예정업무 | G1: 비고 및 이슈 | I1: 1. 타이틀 컬럼 : 노란색 바탕 항목만 입력
A2: =VLOOKUP(B2,기준값설정!$D$2:$E$22,2,FALSE) -> DX | B2: 정우철 | C2: 팀공통 | D2: =VLOOKUP(C2,기준값설정!$A$2:$B$22,2,FALSE) -> 공통2500 | E2: [과제 수주 및 관리] * 보건 RFP18-1낙상 : 사업계획 작성 및 제출 * 보건 RFP 13-2 저출산 : 사업계획 행정 및 제출 | F2: [과제 수주 및 관리] * 정량적, 정성적 목표 세부사항 정리 * 과제별 수행 실무책임자 선정 및 수행 계획 및 목표 수립 * 과제별 계속비 편성 및 기관부담금입금관련 점검 | G2: * 2026 보건 과제 2건 계획서 제출 * 질병관리청 수행 책임자선정 | I2: 2. 내용작성 : 연구개발 항목단위로 행을 분리하여 작성 아래의 형태로 작성 [연구개발항목명] : [] 볼드 *세부연구개발내용 ㄴ상세내용
A3: =VLOOKUP(B3,기준값설정!$D$2:$E$22,2,FALSE) -> DX | B3: 정우철 | C3: 팀공통 | D3: =VLOOKUP(C3,기준값설정!$A$2:$B$22,2,FALSE) -> 공통2500 | F3: [조직 운영 관리] * 조직 체계 및 인원 계획 수립 * 조직 업무 관리 및 보고 체계 방법 수립 | G3: 파트구성 및 인력 계획 수립 | I3: 3. 행추가 시 : 기존 작성된 행을 복사하여 복사한셀 삽입으로 추가할것
A4: =VLOOKUP(B4,기준값설정!$D$2:$E$22,2,FALSE) -> DX | B4: 정우철 | C4: 팀공통 | D4: =VLOOKUP(C4,기준값설정!$A$2:$B$22,2,FALSE) -> 공통2500 | F4: [조직 운영 관리] * 조직 체계 및 인원 계획 수립 * 조직 업무 관리 및 보고 체계 방법 수립 | G4: 파트구성 및 인력 계획 수립 | I4: 4. 프로젝트명 추가 및 수정 시 ㄴ 기준값설정 Sheet 의 프로젝트목록에 추가
A5: =VLOOKUP(B5,기준값설정!$D$2:$E$22,2,FALSE) -> DX | B5: 정우철 | C5: 팀공통 | D5: =VLOOKUP(C5,기준값설정!$A$2:$B$22,2,FALSE) -> 공통2500 | E5: [자체 특허 출원 : 사업방어목적] (가칭)병상 디스플레이를 활용한 IoT 장치 데이터 수집 방안 * 특어 기안 작성 및 특허법인 전달 | F5: [자체 특허 출원 : 사업방어목적] (가칭)병상 디스플레이를 활용한 IoT 장치 데이터 수집 방안 * 특허 출원 진행 | I5: 5. 팀원 추가 시 ㄴ 기준값설정 Sheet 의 프로젝트목록에 추가
A6: =VLOOKUP(B6,기준값설정!$D$2:$E$22,2,FALSE) -> DX | B6: 김영상 | C6: 가상병원_한림(2025년) | D6: =VLOOKUP(C6,기준값설정!$A$2:$B$22,2,FALSE) -> HAX-의료-25004 | E6: [일산병원-자산관리고도화] * 자산고도화 2차 개발건 기능 확인 점검 * 자산 Issue 확인 조치 > 설정 문제 상용 서버 수정 완료 | F6: [일산병원-자산관리고도화] * 병원 내 적용일정 협의 및 배포일정 수립 | I6: 6. 비고 및 중요 내용에 대한 강조 ㄴ 파트장 및 조직장이 꼭 확인해야 할 사항 붉은색 / 볼드 - 폰트색상선택 > 표준색 첫번째 ㄴ 리미인드 차원에서 확인해야 할 사항 파란색 / 볼드 - 폰트색상선택 > 표준색 뒤에서 세번째
A7: =VLOOKUP(B7,기준값설정!$D$2:$E$22,2,FALSE) -> DX | B7: 김영상 | C7: 5G 1세부(현장수요) | D7: =VLOOKUP(C7,기준값설정!$A$2:$B$22,2,FALSE) -> 과제0013 | E7: [단계보고] 준비 * 단계보고서, 발표자료 : 지적사항 수정 및 보강 | F7: [단계보고] 발표평가 (2.4) * 단계평가 수행 및 지적사항 조치 | G7: 일시 / 장소 : 2.4 (수) 1:30 대한상공회의소 8층 7평가장 - 일정점검 : 홍성표
A8: =VLOOKUP(B8,기준값설정!$D$2:$E$22,2,FALSE) -> DX | B8: 김영상 | C8: 5G 1세부(현장수요) | D8: =VLOOKUP(C8,기준값설정!$A$2:$B$22,2,FALSE) -> 과제0013 | E8: [5네트워크 개선] : 원격지 서버 접속 (목적) 원격지 시스템 접속 환경 개선 * 폐쇄망 내외부 통신 방안 개선 (추가비용 발생) ㄴ VPN 장치 및 전용망 구성 비용 : 520만원 예상 | F8: [5네트워크 개선] * 5G 네크워크 방향 비용 승인, 구매절차 수행 | G8: [추가비용 승인 필요] * 원격지 접근을 통한 지방 출장 시 출장 파견 인원 감소 목적
A9: =VLOOKUP(B9,기준값설정!$D$2:$E$22,2,FALSE) -> DX | B9: 김영상 | C9: 5G 1세부(현장수요) | D9: =VLOOKUP(C9,기준값설정!$A$2:$B$22,2,FALSE) -> 과제0013 | E9: [연구개발사항] 완료 * 시설물 전광판 Grade 연동 : 확인 (완료)
A10: =VLOOKUP(B10,기준값설정!$D$2:$E$22,2,FALSE) -> DX | B10: 김영상 | C10: 5G 3세부(재난현장) | D10: =VLOOKUP(C10,기준값설정!$A$2:$B$22,2,FALSE) -> 과제0014 | E10: [단계보고] 준비 '* 단계보고서, 발표자료 : 지적사항 수정 및 보강 | F10: [단계보고] 발표평가 (2.4) * 단계평가 수행 및 지적사항 조치 | G10: 일시 / 장소 : 2.4 (수) 1:30 대한상공회의소 8층 7평가장 - 일정점검 : 한정호
A11: =VLOOKUP(B11,기준값설정!$D$2:$E$22,2,FALSE) -> DX | B11: 정우철 | C11: 가상병원용인 | D11: =VLOOKUP(C11,기준값설정!$A$2:$B$22,2,FALSE) -> 과제0023 | E11: - | F11: -
A12: =VLOOKUP(B12,기준값설정!$D$2:$E$22,2,FALSE) -> DX | B12: 권현하 | C12: 비대면과제 | D12: =VLOOKUP(C12,기준값설정!$A$2:$B$22,2,FALSE) -> 과제0024 | E12: [정량적 성능 지표] * SW 저작권 등록 완료 - 25년성과 누락분 | F12: [정량적 성능 지표] * SW 저작권 - IRIS 성과 등록 및 주관기관 내용 전달
A13: =VLOOKUP(B13,기준값설정!$D$2:$E$22,2,FALSE) -> DX | B13: 권현하 | C13: 비대면과제 | D13: =VLOOKUP(C13,기준값설정!$A$2:$B$22,2,FALSE) -> 과제0024 | E13: [연구개발] - 스카이랩스장비연동 * 스카이랩스 장비 연동 - 요청사항파악 (F.스카이랩스) ㄴ 장치 할당해제 및 결과 연동 전송 | F13: [연구개발] - 스카이랩스장비연동 * 스카이랩스 장비 연동 - 현황파악 및 수행방안 논의 ㄴ 장치 할당해제 및 결과 연동 전송 | G13: * 스카이랩스 수행 방향 협의요청건 * 인수인계 누락 현황파악 필요
A14: =VLOOKUP(B14,기준값설정!$D$2:$E$22,2,FALSE) -> DX | B14: 권현하 | C14: 비대면과제 | D14: =VLOOKUP(C14,기준값설정!$A$2:$B$22,2,FALSE) -> 과제0024 | E14: [연구개발] - 웨어러블 로지스틱 관리 * 일산병원 요청사항 - 1차검토 | F14: [연구개발] - 웨어러블 로지스틱 관리 * 시스템 요구사항 검토 및 분석

Sheet 기준값설정
A1: 프로젝트 목록 | D1: 팀원목록
A2: 프로젝트명 | B2: 프로젝트코드 | D2: 성명 | E2: 파트
A3: 팀공통 | B3: 공통2500 | D3: 정우철 | E3: DX
A4: DX공통 | B4: 공통2500 | D4: 문선홍 | E4: AX
A5: AX공통 | B5: 공통2500 | D5: 이성전 | E5: DX
A6: 5G 1세부(현장수요) | B6: 과제0013 | D6: 김영상 | E6: DX
A7: 5G 3세부(재난현장) | B7: 과제0014 | D7: 김지환 | E7: AX
A8: 가상병원용인 | B8: 과제0023 | D8: 권현하 | E8: DX
A9: 비대면과제 | B9: 과제0024 | D9: 송하은 | E9: AX
A10: 스케일업팁스일산 | B10: 과제0026 | D10: 최혜주 | E10: AX
A11: 질병관리청 AX | B11: 과제0027 | D11: 정원희 | E11: AX
A12: 가상병원_한림(2025년) | B12: HAX-의료-25004
A13: AI영상검사 | B13: 과제0011
